Workbook

Sheet Employee Data
A1: Age | B1: Attrition | C1: BusinessTravel | D1: DailyRate | E1: Department | F1: DistanceFromHome | G1: Education | H1: EducationField | I1: EmployeeCount | J1: EmployeeNumber | K1: EnvironmentSatisfaction | L1: Gender | M1: HourlyRate | N1: JobInvolvement | O1: JobLevel | P1: JobRole | Q1: JobSatisfaction | R1: MaritalStatus | S1: MonthlyIncome | T1: MonthlyRate | U1: NumCompaniesWorked | V1: Over18 | W1: OverTime | X1: PercentSalaryHike | Y1: PerformanceRating | Z1: RelationshipSatisfaction | AA1: StandardHours | AB1: StockOptionLevel | AC1: TotalWorkingYears | AD1: TrainingTimesLastYear | AE1: WorkLifeBalance | AF1: YearsAtCompany | AG1: YearsInCurrentRole | AH1: YearsSinceLastPromotion | AI1: YearsWithCurrManager
A2: 41 | B2: Yes | C2: Travel_Rarely | D2: 1102 | E2: Sales | F2: 1 | G2: 2 | H2: Life Sciences | I2: 1 | J2: 1 | K2: 2 | L2: Female | M2: 94 | N2: 3 | O2: 2 | P2: Sales Executive | Q2: 4 | R2: Single | S2: 5993 | T2: 19479 | U2: 8 | V2: Y | W2: Yes | X2: 11 | Y2: 3 | Z2: 1 | AA2: 80 | AB2: 0 | AC2: 8 | AD2: 0 | AE2: 1 | AF2: 6 | AG2: 4 | AH2: 0 | AI2: 5
A3: 49 | B3: No | C3: Travel_Frequently | D3: 279 | E3: Research & Development | F3: 8 | G3: 1 | H3: Life Sciences | I3: 1 | J3: 2 | K3: 3 | L3: Male | M3: 61 | N3: 2 | O3: 2 | P3: Research Scientist | Q3: 2 | R3: Married | S3: 5130 | T3: 24907 | U3: 1 | V3: Y | W3: No | X3: 23 | Y3: 4 | Z3: 4 | AA3: 80 | AB3: 1 | AC3: 10 | AD3: 3 | AE3: 3 | AF3: 10 | AG3: 7 | AH3: 1 | AI3: 7
A4: 37 | B4: Yes | C4: Travel_Rarely | D4: 1373 | E4: Research & Development | F4: 2 | G4: 2 | H4: Other | I4: 1 | J4: 4 | K4: 4 | L4: Male | M4: 92 | N4: 2 | O4: 1 | P4: Laboratory Technician | Q4: 3 | R4: Single | S4: 2090 | T4: 2396 | U4: 6 | V4: Y | W4: Yes | X4: 15 | Y4: 3 | Z4: 2 | AA4: 80 | AB4: 0 | AC4: 7 | AD4: 3 | AE4: 3 | AF4: 0 | AG4: 0 | AH4: 0 | AI4: 0
A5: 33 | B5: No | C5: Travel_Frequently | D5: 1392 | E5: Research & Development | F5: 3 | G5: 4 | H5: Life Sciences | I5: 1 | J5: 5 | K5: 4 | L5: Female | M5: 56 | N5: 3 | O5: 1 | P5: Research Scientist | Q5: 3 | R5: Married | S5: 2909 | T5: 23159 | U5: 1 | V5: Y | W5: Yes | X5: 11 | Y5: 3 | Z5: 3 | AA5: 80 | AB5: 0 | AC5: 8 | AD5: 3 | AE5: 3 | AF5: 8 | AG5: 7 | AH5: 3 | AI5: 0
A6: 27 | B6: No | C6: Travel_Rarely | D6: 591 | E6: Research & Development | F6: 2 | G6: 1 | H6: Medical | I6: 1 | J6: 7 | K6: 1 | L6: Male | M6: 40 | N6: 3 | O6: 1 | P6: Laboratory Technician | Q6: 2 | R6: Married | S6: 3468 | T6: 16632 | U6: 9 | V6: Y | W6: No | X6: 12 | Y6: 3 | Z6: 4 | AA6: 80 | AB6: 1 | AC6: 6 | AD6: 3 | AE6: 3 | AF6: 2 | AG6: 2 | AH6: 2 | AI6: 2
A7: 32 | B7: No | C7: Travel_Frequently | D7: 1005 | E7: Research & Development | F7: 2 | G7: 2 | H7: Life Sciences | I7: 1 | J7: 8 | K7: 4 | L7: Male | M7: 79 | N7: 3 | O7: 1 | P7: Laboratory Technician | Q7: 4 | R7: Single | S7: 3068 | T7: 11864 | U7: 0 | V7: Y | W7: No | X7: 13 | Y7: 3 | Z7: 3 | AA7: 80 | AB7: 0 | AC7: 8 | AD7: 2 | AE7: 2 | AF7: 7 | AG7: 7 | AH7: 3 | AI7: 6
A8: 59 | B8: No | C8: Travel_Rarely | D8: 1324 | E8: Research & Development | F8: 3 | G8: 3 | H8: Medical | I8: 1 | J8: 10 | K8: 3 | L8: Female | M8: 81 | N8: 4 | O8: 1 | P8: Laboratory Technician | Q8: 1 | R8: Married | S8: 2670 | T8: 9964 | U8: 4 | V8: Y | W8: Yes | X8: 20 | Y8: 4 | Z8: 1 | AA8: 80 | AB8: 3 | AC8: 12 | AD8: 3 | AE8: 2 | AF8: 1 | AG8: 0 | AH8: 0 | AI8: 0
A9: 30 | B9: No | C9: Travel_Rarely | D9: 1358 | E9: Research & Development | F9: 24 | G9: 1 | H9: Life Sciences | I9: 1 | J9: 11 | K9: 4 | L9: Male | M9: 67 | N9: 3 | O9: 1 | P9: Laboratory Technician | Q9: 3 | R9: Divorced | S9: 2693 | T9: 13335 | U9: 1 | V9: Y | W9: No | X9: 22 | Y9: 4 | Z9: 2 | AA9: 80 | AB9: 1 | AC9: 1 | AD9: 2 | AE9: 3 | AF9: 1 | AG9: 0 | AH9: 0 | AI9: 0
A10: 38 | B10: No | C10: Travel_Frequently | D10: 216 | E10: Research & Development | F10: 23 | G10: 3 | H10: Life Sciences | I10: 1 | J10: 12 | K10: 4 | L10: Male | M10: 44 | N10: 2 | O10: 3 | P10: Manufacturing Director | Q10: 3 | R10: Single | S10: 9526 | T10: 8787 | U10: 0 | V10: Y | W10: No | X10: 21 | Y10: 4 | Z10: 2 | AA10: 80 | AB10: 0 | AC10: 10 | AD10: 2 | AE10: 3 | AF10: 9 | AG10: 7 | AH10: 1 | AI10: 8
A11: 36 | B11: No | C11: Travel_Rarely | D11: 1299 | E11: Research & Development | F11: 27 | G11: 3 | H11: Medical | I11: 1 | J11: 13 | K11: 3 | L11: Male | M11: 94 | N11: 3 | O11: 2 | P11: Healthcare Representative | Q11: 3 | R11: Married | S11: 5237 | T11: 16577 | U11: 6 | V11: Y | W11: No | X11: 13 | Y11: 3 | Z11: 2 | AA11: 80 | AB11: 2 | AC11: 17 | AD11: 3 | AE11: 2 | AF11: 7 | AG11: 7 | AH11: 7 | AI11: 7
A12: 35 | B12: No | C12: Travel_Rarely | D12: 809 | E12: Research & Development | F12: 16 | G12: 3 | H12: Medical | I12: 1 | J12: 14 | K12: 1 | L12: Male | M12: 84 | N12: 4 | O12: 1 | P12: Laboratory Technician | Q12: 2 | R12: Married | S12: 2426 | T12: 16479 | U12: 0 | V12: Y | W12: No | X12: 13 | Y12: 3 | Z12: 3 | AA12: 80 | AB12: 1 | AC12: 6 | AD12: 5 | AE12: 3 | AF12: 5 | AG12: 4 | AH12: 0 | AI12: 3
A13: 29 | B13: No | C13: Travel_Rarely | D13: 153 | E13: Research & Development | F13: 15 | G13: 2 | H13: Life Sciences | I13: 1 | J13: 15 | K13: 4 | L13: Female | M13: 49 | N13: 2 | O13: 2 | P13: Laboratory Technician | Q13: 3 | R13: Single | S13: 4193 | T13: 12682 | U13: 0 | V13: Y | W13: Yes | X13: 12 | Y13: 3 | Z13: 4 | AA13: 80 | AB13: 0 | AC13: 10 | AD13: 3 | AE13: 3 | AF13: 9 | AG13: 5 | AH13: 0 | AI13: 8
... A1471: 34 | B1471: No | C1471: Travel_Rarely | D1471: 628 | E1471: Research & Development | F1471: 8 | G1471: 3 | H1471: Medical | I1471: 1 | J1471: 2068 | K1471: 2 | L1471: Male | M1471: 82 | N1471: 4 | O1471: 2 | P1471: Laboratory Technician | Q1471: 3 | R1471: Married | S1471: 4404 | T1471: 10228 | U1471: 2 | V1471: Y | W1471: No | X1471: 12 | Y1471: 3 | Z1471: 1 | AA1471: 80 | AB1471: 0 | AC1471: 6 | AD1471: 3 | AE1471: 4 | AF1471: 4 | AG1471: 3 | AH1471: 1 | AI1471: 2

Sheet Analysis
A2: KPI
A4: Department | B4: Total Employee | C4: Employees Who Left | D4: Overall Attrition Rate
B5: =COUNTA('Employee Data'!J:J)-1 -> 1470 | C5: =COUNTIF('Employee Data'!B:B,"Yes") -> 237 | D5: =COUNTIF('Employee Data'!B:B,"Yes")/(COUNTA('Employee Data'!J:J)-1) -> 0.16122449
A6: Sales | B6: =COUNTIF('Employee Data'!E:E,"Sales") -> 446 | C6: =COUNTIFS('Employee Data'!E:E,"Sales",'Employee Data'!B:B,"Yes") -> 92 | D6: =C6/B6 -> 0.20627803
A7: Research & Development | B7: =COUNTIF('Employee Data'!E:E,"Research & Development") -> 961 | C7: =COUNTIFS('Employee Data'!E:E,"Research & Development",'Employee Data'!B:B,"Yes") -> 133 | D7: =C7/B7 -> 0.1383975
A8: Human Resources | B8: =COUNTIF('Employee Data'!E:E,"Human Resources") -> 63 | C8: =COUNTIFS('Employee Data'!E:E,"Human Resources",'Employee Data'!B:B,"Yes") -> 12 | D8: =C8/B8 -> 0.19047619
A11: Age Group | B11: Total Employees | C11: Employees who left | D11: Attriation Rate
A12: Under 25 | B12: =COUNTIF('Employee Data'!A:A,"<25") -> 97 | C12: =COUNTIFS('Employee Data'!A:A,"<25",'Employee Data'!B:B,"Yes") -> 38 | D12: =C12/B12 -> 0.39175258
A13: 25-34 | B13: =COUNTIFS('Employee Data'!A:A,">=25",'Employee Data'!A:A,"<=34") -> 554 | C13: =COUNTIFS('Employee Data'!A:A,">=25",'Employee Data'!A:A,"<=34",'Employee Data'!B:B,"Yes") -> 112 | D13: =C13/B13 -> 0.20216606
A14: 35-44 | B14: =COUNTIFS('Employee Data'!A:A,">=35",'Employee Data'!A:A,"<=44") -> 505 | C14: =COUNTIFS('Employee Data'!A:A,">=35",'Employee Data'!A:A,"<=44",'Employee Data'!B:B,"Yes") -> 51 | D14: =C14/B14 -> 0.1009901
A15: 45+ | B15: =COUNTIF('Employee Data'!A:A,">=45") -> 314 | C15: =COUNTIFS('Employee Data'!A:A,">=45",'Employee Data'!B:B,"Yes") -> 36 | D15: =C15/B15 -> 0.11464968
A17: Job Role | B17: Total Employees | C17: Employees who left | D17: Attriation Rate
A18: {=_xlfn.UNIQUE('Employee Data'!P2:P1471)} -> Sales Executive | B18: =COUNTIF('Employee Data'!P:P,A18) -> 326 | C18: =COUNTIFS('Employee Data'!P:P,A18,'Employee Data'!B:B,"Yes") -> 57 | D18: =C18/B18 -> 0.17484663
A19: Research Scientist | B19: =COUNTIF('Employee Data'!P:P,A19) -> 292 | C19: =COUNTIFS('Employee Data'!P:P,A19,'Employee Data'!B:B,"Yes") -> 47 | D19: =C19/B19 -> 0.1609589
A20: Laboratory Technician | B20: =COUNTIF('Employee Data'!P:P,A20) -> 259 | C20: =COUNTIFS('Employee Data'!P:P,A20,'Employee Data'!B:B,"Yes") -> 62 | D20: =C20/B20 -> 0.23938224
A21: Manufacturing Director | B21: =COUNTIF('Employee Data'!P:P,A21) -> 145 | C21: =COUNTIFS('Employee Data'!P:P,A21,'Employee Data'!B:B,"Yes") -> 10 | D21: =C21/B21 -> 0.068965517
A22: Healthcare Representative | B22: =COUNTIF('Employee Data'!P:P,A22) -> 131 | C22: =COUNTIFS('Employee Data'!P:P,A22,'Employee Data'!B:B,"Yes") -> 9 | D22: =C22/B22 -> 0.06870229
A23: Manager | B23: =COUNTIF('Employee Data'!P:P,A23) -> 102 | C23: =COUNTIFS('Employee Data'!P:P,A23,'Employee Data'!B:B,"Yes") -> 5 | D23: =C23/B23 -> 0.049019608
A24: Sales Representative | B24: =COUNTIF('Employee Data'!P:P,A24) -> 83 | C24: =COUNTIFS('Employee Data'!P:P,A24,'Employee Data'!B:B,"Yes") -> 33 | D24: =C24/B24 -> 0.39759036
A25: Research Director | B25: =COUNTIF('Employee Data'!P:P,A25) -> 80 | C25: =COUNTIFS('Employee Data'!P:P,A25,'Employee Data'!B:B,"Yes") -> 2 | D25: =C25/B25 -> 0.025
A26: Human Resources | B26: =COUNTIF('Employee Data'!P:P,A26) -> 52 | C26: =COUNTIFS('Employee Data'!P:P,A26,'Employee Data'!B:B,"Yes") -> 12 | D26: =C26/B26 -> 0.23076923
A29: Gender | B29: Total Employees by Gender | C29: Employees Who Left by Gender | D29: Employees Who Left ÷ Total Employees
A30: {=_xlfn.UNIQUE('Employee Data'!L2:L1471)} -> Female | B30: =COUNTIF('Employee Data'!L:L,A30) -> 588 | C30: =COUNTIFS('Employee Data'!L:L,A30,'Employee Data'!B:B,"Yes") -> 87 | D30: =C30/B30 -> 0.14795918
A31: Male | B31: =COUNTIF('Employee Data'!L:L,A31) -> 882 | C31: =COUNTIFS('Employee Data'!L:L,A31,'Employee Data'!B:B,"Yes") -> 150 | D31: =C31/B31 -> 0.17006803
A34: Does Overtime | B34: Total Employees by Overtime. | C34: Employees Who Left | D34: Column1
A35: Yes | B35: =COUNTIF('Employee Data'!W:W,"Yes") -> 416 | C35: =COUNTIFS('Employee Data'!W:W,"Yes",'Employee Data'!B:B,"Yes") -> 127
A36: NO | B36: =COUNTIF('Employee Data'!W:W,"No") -> 1054 | C36: =COUNTIFS('Employee Data'!W:W,"No",'Employee Data'!B:B,"Yes") -> 110
A40: Job Satisfaction | B40: Total Employees | C40: Employees Who Left | D40: Attrition Rate
A41: 1 | B41: =COUNTIF('Employee Data'!Q:Q,A41) -> 289 | C41: =COUNTIFS('Employee Data'!Q:Q,A41,'Employee Data'!B:B,"Yes") -> 66 | D41: =C41/B41 -> 0.2283737
A42: 2 | B42: =COUNTIF('Employee Data'!Q:Q,A42) -> 280 | C42: =COUNTIFS('Employee Data'!Q:Q,A42,'Employee Data'!B:B,"Yes") -> 46 | D42: =C42/B42 -> 0.16428571
A43: 3 | B43: =COUNTIF('Employee Data'!Q:Q,A43) -> 442 | C43: =COUNTIFS('Employee Data'!Q:Q,A43,'Employee Data'!B:B,"Yes") -> 73 | D43: =C43/B43 -> 0.16515837
A44: 4 | B44: =COUNTIF('Employee Data'!Q:Q,A44) -> 459 | C44: =COUNTIFS('Employee Data'!Q:Q,A44,'Employee Data'!B:B,"Yes") -> 52 | D44: =C44/B44 -> 0.11328976
A48: Years at Company | B48: Total Employees | C48: Employees Who Left | D48: Attrition Rate
A49: 0–2 Years | B49: =COUNTIFS('Employee Data'!AF:AF,">=0",'Employee Data'!AF:AF,"<=2") -> 342 | C49: =COUNTIFS('Employee Data'!AF:AF,">=0",'Employee Data'!AF:AF,"<=2",'Employee Data'!B:B,"Yes") -> 102 | D49: =C49/B49 -> 0.29824561
A50: 3–5 Years | B50: =COUNTIFS('Employee Data'!AF:AF,">=3",'Employee Data'!AF:AF,"<=5") -> 434 | C50: =COUNTIFS('Employee Data'!AF:AF,">=3",'Employee Data'!AF:AF,"<=5",'Employee Data'!B:B,"Yes") -> 60 | D50: =C50/B50 -> 0.13824885
A51: 6–10 Years | B51: =COUNTIFS('Employee Data'!AF:AF,">=6",'Employee Data'!AF:AF,"<=10") -> 448 | C51: =COUNTIFS('Employee Data'!AF:AF,">=6",'Employee Data'!AF:AF,"<=10",'Employee Data'!B:B,"Yes") -> 55 | D51: =C51/B51 -> 0.12276786
A52: 11+ Years | B52: =COUNTIF('Employee Data'!AF:AF,">=11") -> 246 | C52: =COUNTIFS('Employee Data'!AF:AF,">=11",'Employee Data'!B:B,"Yes") -> 20 | D52: =C52/B52 -> 0.081300813
A56: Monthly Income Group | B56: Total Employees | C56: Employees Who Left | D56: Attrition Rate
A57: Below 3K | B57: =COUNTIF('Employee Data'!S:S,"<3000") -> 395 | C57: =COUNTIFS('Employee Data'!S:S,"<3000",'Employee Data'!B:B,"Yes") -> 113 | D57: =C57/B57 -> 0.28607595
A58: 3K–5K | B58: =COUNTIFS('Employee Data'!S:S,">=3000",'Employee Data'!S:S,"<=5000") -> 354 | C58: =COUNTIFS('Employee Data'!S:S,">=3000",'Employee Data'!S:S,"<=5000",'Employee Data'!B:B,"Yes") -> 50 | D58: =C58/B58 -> 0.14124294
...
